- `try...catch`：可以解决，但要捕捉所有错误有点麻烦
- `ErrorBoundary`

`Errorboundary` 只捕获在 React 生命周期中发生的错误。在它之外发生的事情，比如已解决的Promise、setTimeout的异步代码、各种回调和事件处理程序，如果没有明确处理，就会遗漏这些错误。

可以通过在所有这些错误中触发重新渲染来使`Errorboundary`捕捉到错误：

```ts
const onClick = () => {
	try {
		fetch()
	} catch (e) {
		setState(() => throw e) // 通过setState触发重渲染
	}
}
```

封装一下：

```ts
// 
const useThrowAsyncError = () => {
  const [state, setState] = useState();
  return (e) => {
    setState(() => throw e)
  }
}

// 
const useCallbackWithErrorHandling = (callback) => {
  const [state, setState] = useState();
  return (...args) => {
    try {
      callback(...args);
    } catch(e) {
      setState(() => throw e);
    }
  }
}

// 使用
const throwAsyncError = useThrowAsyncError();

const onClick = () => {
	try {
		fetch()
	} catch (e) {
		throwAsyncError()
	}
}

// 或者
const onClickWithErrorHandler = useCallbackWithErrorHandling(onClick);
```